Workbook

Sheet Sprint Planning
A1: BondiaCT Control Tower - Sprint Planning & Task Tracker
A2: Proyecto: Validacion Previa de Pedimentos Aduanales | bondiact.io | Actualizado: 6/Abr/2026
A4: Sprint | B4: Task ID | C4: Tarea | D4: Tipo | E4: Archivo(s) Principal(es) | F4: Status | G4: Inicio | H4: Cierre | I4: Story Points | J4: Notas
A5: S1 | B5: S1-01 | C5: Sistema CSS Variables inicial | D5: Infra | E5: animations.css, index.css | F5: DONE | G5: Mar 2026 | H5: Mar 2026 | I5: 5 | J5: Variables :root + 3 temas
A6: S1 | B6: S1-02 | C6: Tematizar Header | D6: UI | E6: Header.tsx | F6: DONE | G6: Mar 2026 | H6: Mar 2026 | I6: 3 | J6: CSS vars aplicadas
A7: S1 | B7: S1-03 | C7: Tematizar BottomNavigation | D7: UI | E7: BottomNavigation.tsx | F7: DONE | G7: Mar 2026 | H7: Mar 2026 | I7: 2
A8: S2 | B8: S2-01 | C8: CustomizePanel tematizado | D8: UI | E8: CustomizePanel.tsx | F8: DONE | G8: Mar 2026 | H8: Mar 2026 | I8: 3
A9: S2 | B9: S2-02 | C9: DashboardToolbar tematizado | D9: UI | E9: DashboardToolbar.tsx | F9: DONE | G9: Mar 2026 | H9: Mar 2026 | I9: 2
A10: S2 | B10: S2-03 | C10: Kanban components | D10: UI | E10: KanbanCard.tsx, KanbanColumnHeader.tsx | F10: DONE | G10: Mar 2026 | H10: Mar 2026 | I10: 5 | J10: Labels IMP/A1/EXP
A11: S2 | B11: S2-04 | C11: ConsultaLIGIE tematizado | D11: UI | E11: ConsultaLIGIE.tsx | F11: DONE | G11: Mar 2026 | H11: Mar 2026 | I11: 3
A12: S2 | B12: S2-05 | C12: ExpedienteDigital tematizado | D12: UI | E12: ExpedienteDigital.tsx | F12: DONE | G12: Mar 2026 | H12: Mar 2026 | I12: 2
A13: S2 | B13: S2-06 | C13: NuevoPedimento tematizado | D13: UI | E13: NuevoPedimento.tsx | F13: DONE | G13: Mar 2026 | H13: Mar 2026 | I13: 3
A14: S3 | B14: S3-01 | C14: Dashboard stats + kanban + tabla | D14: Feature | E14: Dashboard.tsx | F14: DONE | G14: Mar 2026 | H14: Mar 2026 | I14: 8 | J14: Recharts integration
A15: S3 | B15: S3-02 | C15: Reportes tematizado | D15: UI | E15: Reportes.tsx | F15: DONE | G15: Mar 2026 | H15: Mar 2026 | I15: 3
A16: S4 | B16: S4-01 | C16: Fix TS2353 :hover ilegal | D16: Bug Fix | E16: DashboardROI.tsx | F16: DONE | G16: 28/Mar | H16: 28/Mar | I16: 2 | J16: style prop no soporta pseudo-clases
A17: S4 | B17: S4-02 | C17: GanttChartView completo | D17: Feature | E17: GanttChartView.tsx | F17: DONE | G17: 28/Mar | H17: 28/Mar | I17: 8 | J17: Toggle, header, celdas, badges, gridlines
A18: S4 | B18: S4-03 | C18: ValidarPedimento UI | D18: Feature | E18: ValidarPedimento.tsx | F18: DONE | G18: 28/Mar | H18: 28/Mar | I18: 5 | J18: FindingCard, barra accion, preview, filters
A19: S4 | B19: S4-04 | C19: Recharts + MiniGanttChart | D19: Feature | E19: Dashboard.tsx | F19: DONE | G19: 28/Mar | H19: 28/Mar | I19: 5 | J19: exportGradient
A20: S4 | B20: S4-05 | C20: TEMAS CONGELADOS | D20: Decision | E20: animations.css, index.css | F20: DONE | G20: 28/Mar | H20: 28/Mar | I20: 1 | J20: Contraste 10% luminoso optimizado
A21: S5 | B21: S5-01 | C21: LIGIE Engine | D21: Feature | E21: ligieService.ts, ligie.ts | F21: DONE | G21: 29/Mar | H21: 30/Mar | I21: 13 | J21: resolveUnidadAbreviatura, FraccionLIGIE interface
A22: S5 | B22: S5-16 | C22: DME Parser 501/505/506 | D22: Feature | E22: dmeParser.ts (legacy), dataStageParser.ts | F22: DONE | G22: 29/Mar | H22: 30/Mar | I22: 8 | J22: Parser oficial Data Stage
A23: S5 | B23: S5-17 | C23: Regla G16 auditoria pesos | D23: Feature | E23: rules-generales.js | F23: DONE | G23: 29/Mar | H23: 30/Mar | I23: 5 | J23: pesoBruto vs packing list
A24: S5 | B24: S5-18 | C24: Upgrade I10 Art.65 LA | D24: Feature | E24: rules-incoterms-transporte.js | F24: DONE | G24: 29/Mar | H24: 30/Mar | I24: 5 | J24: CRITICO + Art.65/176/178 LA
A25: S5 | B25: S5-19 | C25: Semaforo Importer Monday-style | D25: Feature | E25: SemaforoImporter.tsx | F25: DONE | G25: 29/Mar | H25: 30/Mar | I25: 5
A26: S5 | B26: S5-HF | C26: HOTFIX: pesoBruto, embalaje $0, UMC | D26: Bug Fix | E26: OCRParser.tsx, ligieService.ts | F26: DONE | G26: 30/Mar | H26: 30/Mar | I26: 3 | J26: Literalidad Financiera/Fisica
A27: S6 | B27: S6-01 | C27: LIGIE initFromFetch + cache | D27: Feature | E27: ligieService.ts, App.tsx | F27: DONE | G27: 31/Mar | H27: 31/Mar | I27: 5 | J27: init() sincrono en useEffect
A28: S6 | B28: S6-02 | C28: MXN compliance + G16 pesos | D28: Feature | E28: OCRParser.tsx, ValidarPedimento.tsx | F28: DONE | G28: 31/Mar | H28: 31/Mar | I28: 8 | J28: otros_usd, pesoBrutoPackingList, pesoVolumetrico
A29: S6 | B29: S6-03 | C29: Semaforo widget + Dashboard | D29: UI | E29: SemaforoImporter.tsx, Dashboard.tsx | F29: DONE | G29: 31/Mar | H29: 31/Mar | I29: 3 | J29: CSS vars tematizado
A30: S6 | B30: S6-HF | C30: HOTFIX: P03/P05 motor reglas + sanitizePDF | D30: Bug Fix | E30: rules-partidas.js, ReportGenerator.tsx, ligie.ts | F30: DONE | G30: 31/Mar | H30: 31/Mar | I30: 5 | J30: nico:string[], G16 ghost fix, tsc Vercel
A31: S7 | B31: S7-01 | C31: OCR real pedimentos IMP/EXP | D31: Feature | E31: OCRParser.tsx | F31: DONE | G31: 1/Abr | H31: 6/Abr | I31: 13 | J31: Guia regex, domicilio, Tax ID, linea captura
A32: S7 | B32: S7-02 | C32: cantidad + valorAduana + paisOrigen OCR | D32: Feature | E32: OCRParser.tsx, NuevoPedimento.tsx | F32: DONE | G32: 5/Abr | H32: 6/Abr | I32: 8 | J32: PARTIDA_REGEX_NO_SEC fallback
A33: S7 | B33: S7-03 | C33: G06/G15/P06 false positives fix | D33: Bug Fix | E33: rules-generales.js, rules-partidas.js | F33: DONE | G33: 5/Abr | H33: 6/Abr | I33: 5 | J33: fechaEntrada, referencia, 60+ paises
A34: S7 | B34: S7-04 | C34: PDF report overlap + Latin-1 | D34: Bug Fix | E34: ReportGenerator.tsx | F34: DONE | G34: 5/Abr | H34: 6/Abr | I34: 8 | J34: checkPageBreak, sanitizePDF, emojis->ASCII
A35: S7 | B35: S7-05 | C35: NuevoPedimento mapping OCR fields | D35: Feature | E35: NuevoPedimento.tsx | F35: DONE | G35: 6/Abr | H35: 6/Abr | I35: 5 | J35: G06 referencia, G15 fecha->ISO, F01/F02
A36: S7 | B36: S7-06 | C36: Partidas table expandida PDF | D36: Feature | E36: ReportGenerator.tsx | F36: DONE | G36: 6/Abr | H36: 6/Abr | I36: 3 | J36: +Cant, +Pais, +ValAduana = 8 columnas
A37: S7 | B37: S7-07 | C37: P06 catalogo 60+ paises | D37: Feature | E37: rules-partidas.js | F37: DONE | G37: 6/Abr | H37: 6/Abr | I37: 3 | J37: TUR,COL,ARG,CHL,PER,NLD,BEL,TWN,VNM,etc
A38: S8 | B38: S8-01 | C38: LIGIE dataset completo (fracciones+NICO+RRNA+UMC) | D38: Feature | E38: ligieService.ts, public/data/ | F38: PENDING | I38: 13 | J38: Ex S7-01. window.FRACCIONES
A39: S8 | B39: S8-02 | C39: Remover PEDIMENTO_REAL fallback | D39: Cleanup | E39: OCRParser.tsx | F39: PENDING | I39: 3 | J39: Ex S7-03. cantidad OCR ya funciona
A40: S8 | B40: S8-03 | C40: Vercel infra ligie-index.js | D40: Infra | E40: public/data/ligie-index.js, vite.config | F40: PENDING | I40: 3 | J40: Confirmar /dist/ copia
A41: S8 | B41: S8-04 | C41: G14: fechaEmision + fechaRegistro OCR | D41: Feature | E41: OCRParser.tsx | F41: PENDING | I41: 5 | J41: Solo tenemos fechaEntrada/fechaPago
...

Sheet Gantt Chart
A1: BondiaCT - Gantt Chart (Sprint Timeline)
A3: Sprint | B3: Nombre | C3: Status | D3: Inicio | E3: Cierre | F3: SP | G3: Mar W1 | H3: Mar W2 | I3: Mar W3 | J3: Mar W4 | K3: Mar W5 | L3: Abr W1 | M3: Abr W2
A4: S1 | B4: CSS Variables & Base UI | C4: CLOSED | D4: Mar W1 | E4: Mar W1 | F4: =SUMPRODUCT(('Sprint Planning'!A5:A50="S1")*('Sprint Planning'!I5:I50)) -> 10
A5: S2 | B5: Componentes principales | C5: CLOSED | D5: Mar W2 | E5: Mar W2 | F5: =SUMPRODUCT(('Sprint Planning'!A5:A50="S2")*('Sprint Planning'!I5:I50)) -> 18
A6: S3 | B6: Dashboard & Reportes | C6: CLOSED | D6: Mar W3 | E6: Mar W3 | F6: =SUMPRODUCT(('Sprint Planning'!A5:A50="S3")*('Sprint Planning'!I5:I50)) -> 11
A7: S4 | B7: Gantt, Recharts, Temas Frozen | C7: CLOSED | D7: 28/Mar | E7: 28/Mar | F7: =SUMPRODUCT(('Sprint Planning'!A5:A50="S4")*('Sprint Planning'!I5:I50)) -> 21
A8: S5 | B8: LIGIE Engine + DME + Reglas | C8: CLOSED | D8: 29/Mar | E8: 30/Mar | F8: =SUMPRODUCT(('Sprint Planning'!A5:A50="S5")*('Sprint Planning'!I5:I50)) -> 39
A9: S6 | B9: MXN Compliance + Semaforo | C9: CLOSED | D9: 31/Mar | E9: 31/Mar | F9: =SUMPRODUCT(('Sprint Planning'!A5:A50="S6")*('Sprint Planning'!I5:I50)) -> 21
A10: S7 | B10: El Escudo Dual - OCR Real | C10: CLOSED | D10: 1/Abr | E10: 6/Abr | F10: =SUMPRODUCT(('Sprint Planning'!A5:A50="S7")*('Sprint Planning'!I5:I50)) -> 45
A11: S8 | B11: LIGIE Full + Forense UI | C11: BACKLOG | F11: =SUMPRODUCT(('Sprint Planning'!A5:A50="S8")*('Sprint Planning'!I5:I50)) -> 32
A13: VELOCITY
A14: SP/Sprint (avg): | B14: =ROUND(SUMPRODUCT((B4:B11<>"")*1*(F4:F11))/COUNTIF(C4:C11,"CLOSED"),1) -> 28.1

Sheet Dependencias
A1: BondiaCT - Mapa de Dependencias
A3: ID | B3: Tarea Origen | C3: Depende De | D3: Tipo | E3: Status | F3: Riesgo | G3: Notas
A4: D-01 | B4: S1 CSS Variables | C4: - | D4: Start | E4: Resuelto | F4: Bajo | G4: Fundacion de todo el sistema visual
A5: D-02 | B5: S2-S3 Componentes UI | C5: S1 CSS Variables | D5: FS | E5: Resuelto | F5: Bajo | G5: Requiere sistema de temas funcionando
A6: D-03 | B6: S4 ValidarPedimento UI | C6: S1-S3 Base UI | D6: FS | E6: Resuelto | F6: Bajo | G6: FindingCard necesita CSS vars
A7: D-04 | B7: S4 Temas CONGELADOS | C7: S1-S3 Iteraciones temas | D7: FS | E7: Resuelto | F7: Bajo | G7: Decision: freeze tras optimizar contraste
A8: D-05 | B8: S5 LIGIE Engine | C8: - | D8: Start | E8: Resuelto | F8: Medio | G8: Motor independiente, FraccionLIGIE interface
A9: D-06 | B9: S5 Regla G16 pesos | C9: S5 OCRParser pesoBruto | D9: FS | E9: Resuelto | F9: Alto | G9: Necesita pesoBruto del OCR extraido
A10: D-07 | B10: S5 DME Parser | C10: - | D10: Start | E10: Resuelto | F10: Bajo | G10: dmeParser.ts=legacy, dataStageParser.ts=oficial
A11: D-08 | B11: S6 MXN Compliance | C11: S5 LIGIE + OCRParser | D11: FS | E11: Resuelto | F11: Medio | G11: _usd campos representan MXN en UI
A12: D-09 | B12: S6 LIGIE initFromFetch | C12: S5-01 LIGIE Engine | D12: FS | E12: Resuelto | F12: Alto | G12: CORS bloquea fetch -> init() sincrono
A13: D-10 | B13: S6 P03/P05 motor reglas | C13: S5-01 LIGIE + S6-01 init | D13: FS | E13: Resuelto | F13: Alto | G13: Claves numericas SAT, LIGIE_INDEX O(1)
A14: D-11 | B14: S7 OCR real pedimentos | C14: S5-HF OCRParser base | D14: FS | E14: Resuelto | F14: Alto | G14: Regex rewrite completo para PDF reales
... A22: D-19 | B22: S8-05 Modo Forense UI | C22: S7 NuevoPedimento mapping | D22: FS | E22: Pendiente | F22: Bajo | G22: Toggle visual Validacion/Forense

Sheet Entregables
A1: BondiaCT - Entregables por Sprint
A3: Sprint | B3: Entregable | C3: Categoria | D3: Status | E3: Fecha Entrega | F3: Impacto / Valor de Negocio
A4: S1 | B4: Sistema de temas (Dark/Blue/Light) con CSS Variables | C4: Infra/UX | D4: Entregado | E4: Mar 2026 | F4: Base visual profesional para toda la app. Temas consistentes sin colores hardcodeados.
A5: S2 | B5: 6 componentes UI tematizados | C5: UI | D5: Entregado | E5: Mar 2026 | F5: Experiencia visual coherente en Kanban, ConsultaLIGIE, ExpedienteDigital, NuevoPedimento.
A6: S3 | B6: Dashboard con stats, kanban y Recharts | C6: Feature | D6: Entregado | E6: Mar 2026 | F6: Vista ejecutiva con metricas de operaciones aduanales en tiempo real.
A7: S4 | B7: GanttChartView + ValidarPedimento + Temas congelados | C7: Feature/Decision | D7: Entregado | E7: 28/Mar/2026 | F7: Timeline visual de operaciones. UI de validacion de pedimentos. Estabilidad visual garantizada.
A8: S5 | B8: Motor LIGIE + DME Parser + Reglas G16/I10 + Semaforo | C8: Core Engine | D8: Entregado | E8: 30/Mar/2026 | F8: LIGIE con 8,133 fracciones. Validacion automatica contra Ley Aduanera Arts.65/176/178. Semaforo Monday-style.
A9: S6 | B9: MXN Compliance Anexo 22 + LIGIE cache + Motor reglas P03/P05 | C9: Compliance | D9: Entregado | E9: 31/Mar/2026 | F9: Cumplimiento normativo Anexo 22. Motor de reglas O(1) con LIGIE_INDEX. sanitizePDF para reportes.
A10: S7 | B10: OCR real IMP/EXP + PDF profesional + Catalogo 60+ paises | C10: Core Engine | D10: Entregado | E10: 6/Abr/2026 | F10: Pedimentos reales parseados. PDF sin overlap con Latin-1. G06/G15/P06 sin false positives. Cantidad+ValorAduana+PaisOrigen por partida.
A11: S8 | B11: LIGIE dataset completo + Modo Forense + G14 fechas | C11: Core Engine | D11: Backlog | F11: Dataset completo con NICO/RRNA/UMC. Toggle Validacion/Forense. fechaEmision+fechaRegistro del OCR.

Sheet Velocity
A1: BondiaCT - Sprint Velocity & Metrics
A3: Sprint | B3: SP Planeados | C3: SP Completados | D3: Tasks Total | E3: Tasks Done | F3: % Completado | G3: Duracion (dias) | H3: Velocidad (SP/dia)
A4: S1 | B4: 10 | C4: 10 | D4: 3 | E4: 3 | F4: =IF(B4=0,0,C4/B4) -> 1 | G4: 2 | H4: =IF(G4="-","-",C4/G4) -> 5
A5: S2 | B5: 18 | C5: 18 | D5: 6 | E5: 6 | F5: =IF(B5=0,0,C5/B5) -> 1 | G5: 3 | H5: =IF(G5="-","-",C5/G5) -> 6
A6: S3 | B6: 11 | C6: 11 | D6: 2 | E6: 2 | F6: =IF(B6=0,0,C6/B6) -> 1 | G6: 2 | H6: =IF(G6="-","-",C6/G6) -> 5.5
A7: S4 | B7: 21 | C7: 21 | D7: 5 | E7: 5 | F7: =IF(B7=0,0,C7/B7) -> 1 | G7: 1 | H7: =IF(G7="-","-",C7/G7) -> 21
A8: S5 | B8: 39 | C8: 39 | D8: 6 | E8: 6 | F8: =IF(B8=0,0,C8/B8) -> 1 | G8: 2 | H8: =IF(G8="-","-",C8/G8) -> 19.5
A9: S6 | B9: 21 | C9: 21 | D9: 4 | E9: 4 | F9: =IF(B9=0,0,C9/B9) -> 1 | G9: 1 | H9: =IF(G9="-","-",C9/G9) -> 21
A10: S7 | B10: 45 | C10: 45 | D10: 7 | E10: 7 | F10: =IF(B10=0,0,C10/B10) -> 1 | G10: 6 | H10: =IF(G10="-","-",C10/G10) -> 7.5
A11: S8 | B11: 32 | C11: 0 | D11: 5 | E11: 0 | F11: =IF(B11=0,0,C11/B11) -> 0 | G11: - | H11: -
A13: TOTAL | B13: =SUM(B4:B11) -> 197 | C13: =SUM(C4:C11) -> 165 | D13: =SUM(D4:D11) -> 38 | E13: =SUM(E4:E11) -> 33 | F13: =IF(B13=0,0,C13/B13) -> 0.83756345
A14: PROMEDIO | B14: =ROUND(AVERAGE(B4:B11),1) -> 24.6 | C14: =ROUND(AVERAGE(C4:C10),1) -> 23.6 | H14: =ROUND(C13/SUM(G4:G10),1) -> 9.7
